package com.javaweek.exception;


/***Once an exception occurs in try block, the execution passes to corresponding catch statement 
 * and doesnï¿½t return back to try block. Only one of the catch blocks are executed at a time. 
 * finally block is always executed whether or not the exception occurred.**/

public class ExceptionDemo1 
{ 
	public static void main(String[] args) 
	{ 
		try
		{ 
			System.out.printf("1\t"); 
			int sum = 9 / 0; 
			System.out.printf("2\t"); 
		} 
		catch(ArithmeticException e) 
		{ 
			System.out.printf("3\t"); 
		} 
		catch(Exception e) 
		{ 
			System.out.printf("4\t"); 
		} 
		finally
		{ 
			System.out.printf("5\t"); 
		} 
	} 
} 
